Failure # 1 (occurred at 2023-12-12_13-17-03)
The actor died because of an error raised in its creation task, [36mray::PPO.__init__()[39m (pid=297223, ip=10.42.0.65, actor_id=db9f81b82f03a7a90349c64201000000, repr=PPO)
  File "/usr/local/lib/python3.7/dist-packages/ray/rllib/algorithms/algorithm.py", line 520, in __init__
    **kwargs,
  File "/usr/local/lib/python3.7/dist-packages/ray/tune/trainable/trainable.py", line 185, in __init__
    self.setup(copy.deepcopy(self.config))
  File "/usr/local/lib/python3.7/dist-packages/ray/rllib/algorithms/algorithm.py", line 646, in setup
    logdir=self.logdir,
  File "/usr/local/lib/python3.7/dist-packages/ray/rllib/evaluation/worker_set.py", line 161, in __init__
    local_worker=local_worker,
  File "/usr/local/lib/python3.7/dist-packages/ray/rllib/evaluation/worker_set.py", line 254, in _setup
    spaces=spaces,
  File "/usr/local/lib/python3.7/dist-packages/ray/rllib/evaluation/worker_set.py", line 935, in _make_worker
    dataset_shards=self._ds_shards,
  File "/usr/local/lib/python3.7/dist-packages/ray/rllib/evaluation/rollout_worker.py", line 397, in __init__
    self.env = env_creator(copy.deepcopy(self.env_context))
  File "carla_RL/train_RL.py", line 24, in env_creator
    return EnvCompatibility(CarlaEnv())
  File "/usr/local/lib/python3.7/dist-packages/gym_carla/envs/carla_env.py", line 122, in __init__
    self.world = client.load_world(env_config['town'])
RuntimeError: time-out of 10000ms while waiting for the simulator, make sure the simulator is ready and connected to localhost:2000
